{
 "cells": [
  {
   "cell_type": "code",
   "execution_count": 8,
   "metadata": {},
   "outputs": [
    {
     "name": "stdout",
     "output_type": "stream",
     "text": [
      "ERROR! Session/line number was not unique in database. History logging moved to new session 8\n"
     ]
    }
   ],
   "source": [
    "import pandas as pd\n",
    "import numpy as np"
   ]
  },
  {
   "cell_type": "code",
   "execution_count": 9,
   "metadata": {},
   "outputs": [
    {
     "name": "stdout",
     "output_type": "stream",
     "text": [
      "ERROR! Session/line number was not unique in database. History logging moved to new session 10\n",
      "C17H14O4S\n",
      "314.4\n"
     ]
    }
   ],
   "source": [
    "import pubchempy as pcp\n",
    "\n",
    "tnf = pcp.Compound.from_cid(5090)\n",
    "print(tnf.molecular_formula)\n",
    "print(tnf.molecular_weight)"
   ]
  },
  {
   "cell_type": "code",
   "execution_count": null,
   "metadata": {},
   "outputs": [
    {
     "name": "stdout",
     "output_type": "stream",
     "text": [
      "ERROR! Session/line number was not unique in database. History logging moved to new session 9\n"
     ]
    },
    {
     "name": "stderr",
     "output_type": "stream",
     "text": [
      "ERROR:root:Internal Python error in the inspect module.\n",
      "Below is the traceback from this internal error.\n",
      "\n",
      "ERROR:root:Internal Python error in the inspect module.\n",
      "Below is the traceback from this internal error.\n",
      "\n",
      "ERROR:root:Internal Python error in the inspect module.\n",
      "Below is the traceback from this internal error.\n",
      "\n"
     ]
    },
    {
     "name": "stdout",
     "output_type": "stream",
     "text": [
      "Initializing model in test mode.\n",
      "Loading model.\n",
      "Traceback (most recent call last):\n",
      "  File \"/opt/conda/envs/pyfingerprint/lib/python3.7/site-packages/IPython/core/interactiveshell.py\", line 3457, in run_code\n",
      "    exec(code_obj, self.user_global_ns, self.user_ns)\n",
      "  File \"/tmp/ipykernel_24/4290654438.py\", line 22, in <module>\n",
      "    output[f] = get_fingerprint(smi, f)\n",
      "  File \"/opt/conda/envs/pyfingerprint/lib/python3.7/site-packages/PyFingerprint/fingerprint.py\", line 82, in get_fingerprint\n",
      "    values = list(hc_fingerprint(smi))\n",
      "  File \"/opt/conda/envs/pyfingerprint/lib/python3.7/site-packages/PyFingerprint/heteroencoder.py\", line 2016, in hc_fingerprint\n",
      "    model = DDC(model_name = model_name)\n",
      "  File \"/opt/conda/envs/pyfingerprint/lib/python3.7/site-packages/PyFingerprint/heteroencoder.py\", line 248, in __init__\n",
      "    self.__load(self.model_name)\n",
      "  File \"/opt/conda/envs/pyfingerprint/lib/python3.7/site-packages/PyFingerprint/heteroencoder.py\", line 830, in __load\n",
      "    with zipfile.ZipFile(model_name + \".zip\", \"r\") as zip_ref:\n",
      "  File \"/opt/conda/envs/pyfingerprint/lib/python3.7/zipfile.py\", line 1240, in __init__\n",
      "    self.fp = io.open(file, filemode)\n",
      "FileNotFoundError: [Errno 2] No such file or directory: '/opt/conda/envs/pyfingerprint/lib/python3.7/site-packages/PyFingerprint/Heteroencoder/heteroencoder_model.pkl.zip'\n",
      "\n",
      "During handling of the above exception, another exception occurred:\n",
      "\n",
      "Traceback (most recent call last):\n",
      "  File \"/opt/conda/envs/pyfingerprint/lib/python3.7/site-packages/IPython/core/interactiveshell.py\", line 2077, in showtraceback\n",
      "    stb = value._render_traceback_()\n",
      "AttributeError: 'FileNotFoundError' object has no attribute '_render_traceback_'\n",
      "\n",
      "During handling of the above exception, another exception occurred:\n",
      "\n",
      "Traceback (most recent call last):\n",
      "  File \"/opt/conda/envs/pyfingerprint/lib/python3.7/site-packages/IPython/core/ultratb.py\", line 1101, in get_records\n",
      "    return _fixed_getinnerframes(etb, number_of_lines_of_context, tb_offset)\n",
      "  File \"/opt/conda/envs/pyfingerprint/lib/python3.7/site-packages/IPython/core/ultratb.py\", line 248, in wrapped\n",
      "    return f(*args, **kwargs)\n",
      "  File \"/opt/conda/envs/pyfingerprint/lib/python3.7/site-packages/IPython/core/ultratb.py\", line 281, in _fixed_getinnerframes\n",
      "    records = fix_frame_records_filenames(inspect.getinnerframes(etb, context))\n",
      "  File \"/opt/conda/envs/pyfingerprint/lib/python3.7/inspect.py\", line 1502, in getinnerframes\n",
      "    frameinfo = (tb.tb_frame,) + getframeinfo(tb, context)\n",
      "  File \"/opt/conda/envs/pyfingerprint/lib/python3.7/inspect.py\", line 1460, in getframeinfo\n",
      "    filename = getsourcefile(frame) or getfile(frame)\n",
      "  File \"/opt/conda/envs/pyfingerprint/lib/python3.7/inspect.py\", line 696, in getsourcefile\n",
      "    if getattr(getmodule(object, filename), '__loader__', None) is not None:\n",
      "  File \"/opt/conda/envs/pyfingerprint/lib/python3.7/inspect.py\", line 733, in getmodule\n",
      "    if ismodule(module) and hasattr(module, '__file__'):\n",
      "  File \"/opt/conda/envs/pyfingerprint/lib/python3.7/site-packages/tensorflow/__init__.py\", line 50, in __getattr__\n",
      "    from ._api.v2 import bitwise\n",
      "  File \"/opt/conda/envs/pyfingerprint/lib/python3.7/site-packages/tensorflow/__init__.py\", line 44, in _load\n",
      "  File \"/opt/conda/envs/pyfingerprint/lib/python3.7/importlib/__init__.py\", line 127, in import_module\n",
      "    return _bootstrap._gcd_import(name[level:], package, level)\n",
      "  File \"<frozen importlib._bootstrap>\", line 1006, in _gcd_import\n",
      "  File \"<frozen importlib._bootstrap>\", line 983, in _find_and_load\n",
      "  File \"<frozen importlib._bootstrap>\", line 965, in _find_and_load_unlocked\n",
      "ModuleNotFoundError: No module named 'tensorflow_core.estimator'\n",
      "Traceback (most recent call last):\n",
      "  File \"/opt/conda/envs/pyfingerprint/lib/python3.7/site-packages/IPython/core/interactiveshell.py\", line 3457, in run_code\n",
      "    exec(code_obj, self.user_global_ns, self.user_ns)\n",
      "  File \"/tmp/ipykernel_24/4290654438.py\", line 22, in <module>\n",
      "    output[f] = get_fingerprint(smi, f)\n",
      "  File \"/opt/conda/envs/pyfingerprint/lib/python3.7/site-packages/PyFingerprint/fingerprint.py\", line 82, in get_fingerprint\n",
      "    values = list(hc_fingerprint(smi))\n",
      "  File \"/opt/conda/envs/pyfingerprint/lib/python3.7/site-packages/PyFingerprint/heteroencoder.py\", line 2016, in hc_fingerprint\n",
      "    model = DDC(model_name = model_name)\n",
      "  File \"/opt/conda/envs/pyfingerprint/lib/python3.7/site-packages/PyFingerprint/heteroencoder.py\", line 248, in __init__\n",
      "    self.__load(self.model_name)\n",
      "  File \"/opt/conda/envs/pyfingerprint/lib/python3.7/site-packages/PyFingerprint/heteroencoder.py\", line 830, in __load\n",
      "    with zipfile.ZipFile(model_name + \".zip\", \"r\") as zip_ref:\n",
      "  File \"/opt/conda/envs/pyfingerprint/lib/python3.7/zipfile.py\", line 1240, in __init__\n",
      "    self.fp = io.open(file, filemode)\n",
      "FileNotFoundError: [Errno 2] No such file or directory: '/opt/conda/envs/pyfingerprint/lib/python3.7/site-packages/PyFingerprint/Heteroencoder/heteroencoder_model.pkl.zip'\n",
      "\n",
      "During handling of the above exception, another exception occurred:\n",
      "\n",
      "Traceback (most recent call last):\n",
      "  File \"/opt/conda/envs/pyfingerprint/lib/python3.7/site-packages/IPython/core/interactiveshell.py\", line 2077, in showtraceback\n",
      "    stb = value._render_traceback_()\n",
      "AttributeError: 'FileNotFoundError' object has no attribute '_render_traceback_'\n",
      "\n",
      "During handling of the above exception, another exception occurred:\n",
      "\n",
      "Traceback (most recent call last):\n",
      "  File \"/opt/conda/envs/pyfingerprint/lib/python3.7/site-packages/IPython/core/interactiveshell.py\", line 3377, in run_ast_nodes\n",
      "    if (await self.run_code(code, result,  async_=asy)):\n",
      "  File \"/opt/conda/envs/pyfingerprint/lib/python3.7/site-packages/IPython/core/interactiveshell.py\", line 3474, in run_code\n",
      "    self.showtraceback(running_compiled_code=True)\n",
      "  File \"/opt/conda/envs/pyfingerprint/lib/python3.7/site-packages/IPython/core/interactiveshell.py\", line 2080, in showtraceback\n",
      "    value, tb, tb_offset=tb_offset)\n",
      "  File \"/opt/conda/envs/pyfingerprint/lib/python3.7/site-packages/IPython/core/ultratb.py\", line 1368, in structured_traceback\n",
      "    self, etype, value, tb, tb_offset, number_of_lines_of_context)\n",
      "  File \"/opt/conda/envs/pyfingerprint/lib/python3.7/site-packages/IPython/core/ultratb.py\", line 1268, in structured_traceback\n",
      "    self, etype, value, tb, tb_offset, number_of_lines_of_context\n",
      "  File \"/opt/conda/envs/pyfingerprint/lib/python3.7/site-packages/IPython/core/ultratb.py\", line 1125, in structured_traceback\n",
      "    tb_offset)\n",
      "  File \"/opt/conda/envs/pyfingerprint/lib/python3.7/site-packages/IPython/core/ultratb.py\", line 1082, in format_exception_as_a_whole\n",
      "    last_unique, recursion_repeat = find_recursion(orig_etype, evalue, records)\n",
      "  File \"/opt/conda/envs/pyfingerprint/lib/python3.7/site-packages/IPython/core/ultratb.py\", line 382, in find_recursion\n",
      "    return len(records), 0\n",
      "TypeError: object of type 'NoneType' has no len()\n",
      "\n",
      "During handling of the above exception, another exception occurred:\n",
      "\n",
      "Traceback (most recent call last):\n",
      "  File \"/opt/conda/envs/pyfingerprint/lib/python3.7/site-packages/IPython/core/interactiveshell.py\", line 2077, in showtraceback\n",
      "    stb = value._render_traceback_()\n",
      "AttributeError: 'TypeError' object has no attribute '_render_traceback_'\n",
      "\n",
      "During handling of the above exception, another exception occurred:\n",
      "\n",
      "Traceback (most recent call last):\n",
      "  File \"/opt/conda/envs/pyfingerprint/lib/python3.7/site-packages/IPython/core/ultratb.py\", line 1101, in get_records\n",
      "    return _fixed_getinnerframes(etb, number_of_lines_of_context, tb_offset)\n",
      "  File \"/opt/conda/envs/pyfingerprint/lib/python3.7/site-packages/IPython/core/ultratb.py\", line 248, in wrapped\n",
      "    return f(*args, **kwargs)\n",
      "  File \"/opt/conda/envs/pyfingerprint/lib/python3.7/site-packages/IPython/core/ultratb.py\", line 281, in _fixed_getinnerframes\n",
      "    records = fix_frame_records_filenames(inspect.getinnerframes(etb, context))\n",
      "  File \"/opt/conda/envs/pyfingerprint/lib/python3.7/inspect.py\", line 1502, in getinnerframes\n",
      "    frameinfo = (tb.tb_frame,) + getframeinfo(tb, context)\n",
      "  File \"/opt/conda/envs/pyfingerprint/lib/python3.7/inspect.py\", line 1460, in getframeinfo\n",
      "    filename = getsourcefile(frame) or getfile(frame)\n",
      "  File \"/opt/conda/envs/pyfingerprint/lib/python3.7/inspect.py\", line 696, in getsourcefile\n",
      "    if getattr(getmodule(object, filename), '__loader__', None) is not None:\n",
      "  File \"/opt/conda/envs/pyfingerprint/lib/python3.7/inspect.py\", line 733, in getmodule\n",
      "    if ismodule(module) and hasattr(module, '__file__'):\n",
      "  File \"/opt/conda/envs/pyfingerprint/lib/python3.7/site-packages/tensorflow/__init__.py\", line 50, in __getattr__\n",
      "    from ._api.v2 import bitwise\n",
      "  File \"/opt/conda/envs/pyfingerprint/lib/python3.7/site-packages/tensorflow/__init__.py\", line 44, in _load\n",
      "  File \"/opt/conda/envs/pyfingerprint/lib/python3.7/importlib/__init__.py\", line 127, in import_module\n",
      "    return _bootstrap._gcd_import(name[level:], package, level)\n",
      "  File \"<frozen importlib._bootstrap>\", line 1006, in _gcd_import\n",
      "  File \"<frozen importlib._bootstrap>\", line 983, in _find_and_load\n",
      "  File \"<frozen importlib._bootstrap>\", line 965, in _find_and_load_unlocked\n",
      "ModuleNotFoundError: No module named 'tensorflow_core.estimator'\n",
      "Traceback (most recent call last):\n",
      "  File \"/opt/conda/envs/pyfingerprint/lib/python3.7/site-packages/IPython/core/interactiveshell.py\", line 3457, in run_code\n",
      "    exec(code_obj, self.user_global_ns, self.user_ns)\n",
      "  File \"/tmp/ipykernel_24/4290654438.py\", line 22, in <module>\n",
      "    output[f] = get_fingerprint(smi, f)\n",
      "  File \"/opt/conda/envs/pyfingerprint/lib/python3.7/site-packages/PyFingerprint/fingerprint.py\", line 82, in get_fingerprint\n",
      "    values = list(hc_fingerprint(smi))\n",
      "  File \"/opt/conda/envs/pyfingerprint/lib/python3.7/site-packages/PyFingerprint/heteroencoder.py\", line 2016, in hc_fingerprint\n",
      "    model = DDC(model_name = model_name)\n",
      "  File \"/opt/conda/envs/pyfingerprint/lib/python3.7/site-packages/PyFingerprint/heteroencoder.py\", line 248, in __init__\n",
      "    self.__load(self.model_name)\n",
      "  File \"/opt/conda/envs/pyfingerprint/lib/python3.7/site-packages/PyFingerprint/heteroencoder.py\", line 830, in __load\n",
      "    with zipfile.ZipFile(model_name + \".zip\", \"r\") as zip_ref:\n",
      "  File \"/opt/conda/envs/pyfingerprint/lib/python3.7/zipfile.py\", line 1240, in __init__\n",
      "    self.fp = io.open(file, filemode)\n",
      "FileNotFoundError: [Errno 2] No such file or directory: '/opt/conda/envs/pyfingerprint/lib/python3.7/site-packages/PyFingerprint/Heteroencoder/heteroencoder_model.pkl.zip'\n",
      "\n",
      "During handling of the above exception, another exception occurred:\n",
      "\n",
      "Traceback (most recent call last):\n",
      "  File \"/opt/conda/envs/pyfingerprint/lib/python3.7/site-packages/IPython/core/interactiveshell.py\", line 2077, in showtraceback\n",
      "    stb = value._render_traceback_()\n",
      "AttributeError: 'FileNotFoundError' object has no attribute '_render_traceback_'\n",
      "\n",
      "During handling of the above exception, another exception occurred:\n",
      "\n",
      "Traceback (most recent call last):\n",
      "  File \"/opt/conda/envs/pyfingerprint/lib/python3.7/site-packages/IPython/core/interactiveshell.py\", line 3377, in run_ast_nodes\n",
      "    if (await self.run_code(code, result,  async_=asy)):\n",
      "  File \"/opt/conda/envs/pyfingerprint/lib/python3.7/site-packages/IPython/core/interactiveshell.py\", line 3474, in run_code\n",
      "    self.showtraceback(running_compiled_code=True)\n",
      "  File \"/opt/conda/envs/pyfingerprint/lib/python3.7/site-packages/IPython/core/interactiveshell.py\", line 2080, in showtraceback\n",
      "    value, tb, tb_offset=tb_offset)\n",
      "  File \"/opt/conda/envs/pyfingerprint/lib/python3.7/site-packages/IPython/core/ultratb.py\", line 1368, in structured_traceback\n",
      "    self, etype, value, tb, tb_offset, number_of_lines_of_context)\n",
      "  File \"/opt/conda/envs/pyfingerprint/lib/python3.7/site-packages/IPython/core/ultratb.py\", line 1268, in structured_traceback\n",
      "    self, etype, value, tb, tb_offset, number_of_lines_of_context\n",
      "  File \"/opt/conda/envs/pyfingerprint/lib/python3.7/site-packages/IPython/core/ultratb.py\", line 1125, in structured_traceback\n",
      "    tb_offset)\n",
      "  File \"/opt/conda/envs/pyfingerprint/lib/python3.7/site-packages/IPython/core/ultratb.py\", line 1082, in format_exception_as_a_whole\n",
      "    last_unique, recursion_repeat = find_recursion(orig_etype, evalue, records)\n",
      "  File \"/opt/conda/envs/pyfingerprint/lib/python3.7/site-packages/IPython/core/ultratb.py\", line 382, in find_recursion\n",
      "    return len(records), 0\n",
      "TypeError: object of type 'NoneType' has no len()\n",
      "\n",
      "During handling of the above exception, another exception occurred:\n",
      "\n",
      "Traceback (most recent call last):\n",
      "  File \"/opt/conda/envs/pyfingerprint/lib/python3.7/site-packages/IPython/core/interactiveshell.py\", line 2077, in showtraceback\n",
      "    stb = value._render_traceback_()\n",
      "AttributeError: 'TypeError' object has no attribute '_render_traceback_'\n",
      "\n",
      "During handling of the above exception, another exception occurred:\n",
      "\n",
      "Traceback (most recent call last):\n",
      "  File \"/opt/conda/envs/pyfingerprint/lib/python3.7/site-packages/IPython/core/interactiveshell.py\", line 2960, in _run_cell\n",
      "    return runner(coro)\n",
      "  File \"/opt/conda/envs/pyfingerprint/lib/python3.7/site-packages/IPython/core/async_helpers.py\", line 78, in _pseudo_sync_runner\n",
      "    coro.send(None)\n",
      "  File \"/opt/conda/envs/pyfingerprint/lib/python3.7/site-packages/IPython/core/interactiveshell.py\", line 3186, in run_cell_async\n",
      "    interactivity=interactivity, compiler=compiler, result=result)\n",
      "  File \"/opt/conda/envs/pyfingerprint/lib/python3.7/site-packages/IPython/core/interactiveshell.py\", line 3396, in run_ast_nodes\n",
      "    self.showtraceback()\n",
      "  File \"/opt/conda/envs/pyfingerprint/lib/python3.7/site-packages/IPython/core/interactiveshell.py\", line 2080, in showtraceback\n",
      "    value, tb, tb_offset=tb_offset)\n",
      "  File \"/opt/conda/envs/pyfingerprint/lib/python3.7/site-packages/IPython/core/ultratb.py\", line 1368, in structured_traceback\n",
      "    self, etype, value, tb, tb_offset, number_of_lines_of_context)\n",
      "  File \"/opt/conda/envs/pyfingerprint/lib/python3.7/site-packages/IPython/core/ultratb.py\", line 1268, in structured_traceback\n",
      "    self, etype, value, tb, tb_offset, number_of_lines_of_context\n",
      "  File \"/opt/conda/envs/pyfingerprint/lib/python3.7/site-packages/IPython/core/ultratb.py\", line 1143, in structured_traceback\n",
      "    chained_exceptions_tb_offset)\n",
      "  File \"/opt/conda/envs/pyfingerprint/lib/python3.7/site-packages/IPython/core/ultratb.py\", line 1082, in format_exception_as_a_whole\n",
      "    last_unique, recursion_repeat = find_recursion(orig_etype, evalue, records)\n",
      "  File \"/opt/conda/envs/pyfingerprint/lib/python3.7/site-packages/IPython/core/ultratb.py\", line 382, in find_recursion\n",
      "    return len(records), 0\n",
      "TypeError: object of type 'NoneType' has no len()\n",
      "\n",
      "During handling of the above exception, another exception occurred:\n",
      "\n",
      "Traceback (most recent call last):\n",
      "  File \"/opt/conda/envs/pyfingerprint/lib/python3.7/site-packages/IPython/core/interactiveshell.py\", line 2077, in showtraceback\n",
      "    stb = value._render_traceback_()\n",
      "AttributeError: 'TypeError' object has no attribute '_render_traceback_'\n",
      "\n",
      "During handling of the above exception, another exception occurred:\n",
      "\n",
      "Traceback (most recent call last):\n",
      "  File \"/opt/conda/envs/pyfingerprint/lib/python3.7/site-packages/IPython/core/ultratb.py\", line 1101, in get_records\n",
      "    return _fixed_getinnerframes(etb, number_of_lines_of_context, tb_offset)\n",
      "  File \"/opt/conda/envs/pyfingerprint/lib/python3.7/site-packages/IPython/core/ultratb.py\", line 248, in wrapped\n",
      "    return f(*args, **kwargs)\n",
      "  File \"/opt/conda/envs/pyfingerprint/lib/python3.7/site-packages/IPython/core/ultratb.py\", line 281, in _fixed_getinnerframes\n",
      "    records = fix_frame_records_filenames(inspect.getinnerframes(etb, context))\n",
      "  File \"/opt/conda/envs/pyfingerprint/lib/python3.7/inspect.py\", line 1502, in getinnerframes\n",
      "    frameinfo = (tb.tb_frame,) + getframeinfo(tb, context)\n",
      "  File \"/opt/conda/envs/pyfingerprint/lib/python3.7/inspect.py\", line 1460, in getframeinfo\n",
      "    filename = getsourcefile(frame) or getfile(frame)\n",
      "  File \"/opt/conda/envs/pyfingerprint/lib/python3.7/inspect.py\", line 696, in getsourcefile\n",
      "    if getattr(getmodule(object, filename), '__loader__', None) is not None:\n",
      "  File \"/opt/conda/envs/pyfingerprint/lib/python3.7/inspect.py\", line 733, in getmodule\n",
      "    if ismodule(module) and hasattr(module, '__file__'):\n",
      "  File \"/opt/conda/envs/pyfingerprint/lib/python3.7/site-packages/tensorflow/__init__.py\", line 50, in __getattr__\n",
      "    from ._api.v2 import bitwise\n",
      "  File \"/opt/conda/envs/pyfingerprint/lib/python3.7/site-packages/tensorflow/__init__.py\", line 44, in _load\n",
      "  File \"/opt/conda/envs/pyfingerprint/lib/python3.7/importlib/__init__.py\", line 127, in import_module\n",
      "    return _bootstrap._gcd_import(name[level:], package, level)\n",
      "  File \"<frozen importlib._bootstrap>\", line 1006, in _gcd_import\n",
      "  File \"<frozen importlib._bootstrap>\", line 983, in _find_and_load\n",
      "  File \"<frozen importlib._bootstrap>\", line 965, in _find_and_load_unlocked\n",
      "ModuleNotFoundError: No module named 'tensorflow_core.estimator'\n"
     ]
    }
   ],
   "source": [
    "import numpy as np\n",
    "from PyFingerprint.fingerprint import get_fingerprint, get_fingerprints\n",
    "\n",
    "cdktypes = ['standard', 'extended', 'graph', 'maccs', 'pubchem', 'estate', 'hybridization', 'lingo', \n",
    "            'klekota-roth', 'shortestpath', 'signature', 'substructure']\n",
    "rdktypes = ['rdkit', 'morgan', 'rdk-maccs', 'topological-torsion', 'avalon', 'atom-pair']\n",
    "babeltypes = ['fp2', 'fp3', 'fp4']\n",
    "vectypes = ['mol2vec', 'heteroencoder']\n",
    "\n",
    "smi = 'CCCCN'\n",
    "output = {}\n",
    "for f in cdktypes:\n",
    "    output[f] = get_fingerprint(smi, f)\n",
    "\n",
    "for f in rdktypes:\n",
    "    output[f] = get_fingerprint(smi, f)\n",
    "    \n",
    "for f in babeltypes:\n",
    "    output[f] = get_fingerprint(smi, f)\n",
    "    \n",
    "for f in vectypes:\n",
    "    output[f] = get_fingerprint(smi, f)\n",
    "\n",
    "output_np = output.copy()\n",
    "for k, fp in output.items():\n",
    "    output_np[k] = fp.to_numpy()"
   ]
  },
  {
   "cell_type": "code",
   "execution_count": null,
   "metadata": {},
   "outputs": [],
   "source": []
  }
 ],
 "metadata": {
  "kernelspec": {
   "display_name": "Python 3 (ipykernel)",
   "language": "python",
   "name": "python3"
  },
  "language_info": {
   "codemirror_mode": {
    "name": "ipython",
    "version": 3
   },
   "file_extension": ".py",
   "mimetype": "text/x-python",
   "name": "python",
   "nbconvert_exporter": "python",
   "pygments_lexer": "ipython3",
   "version": "3.7.16"
  }
 },
 "nbformat": 4,
 "nbformat_minor": 4
}
